Workbook

Sheet Balance Sheet
A1: Balance Sheet
A2: As of 31 Dec 2025
A3: Line Item | B3: Amount (USD)
A4: ASSETS
A5: Current Assets
A6: Cash & Cash Equivalents | B6: 220000
A7: Accounts Receivable | B7: 35000
A8: Inventory | B8: 85000
A9: Prepaid Expenses | B9: 40000
A10: Total Current Assets | B10: =SUM(B6:B9) -> 380000
A12: Non-Current Assets
A13: Property & Equipment | B13: 1050000
A14: Less: Accumulated Depreciation | B14: -210000
A15: Net Property & Equipment | B15: =B13+B14 -> 840000
A16: TOTAL ASSETS | B16: =B10+B15 -> 1220000
A18: LIABILITIES
A19: Current Liabilities
A20: Accounts Payable | B20: 120000
A21: Accrued Payroll | B21: 110000
A22: Sales Tax Payable | B22: 65000
A23: Other Accrued Expenses | B23: 25000
A24: Total Current Liabilities | B24: =SUM(B20:B23) -> 320000
A25: TOTAL LIABILITIES | B25: =B24 -> 320000
A27: EQUITY
A28: Owner Capital / Paid-in Equity | B28: 730000
A29: Retained Earnings – 2025 | B29: 170000
A30: Total Equity | B30: =SUM(B28:B29) -> 900000
A31: TOTAL LIABILITIES + EQUITY | B31: =B25+B30 -> 1220000

Sheet PandL
A1: Income Statement
A2: Year ending 31st Dec 2025
A3: Line Item | B3: Amount (USD)
A4: Net Revenue (Sales)
A5: Sales Revenue – Cappuccino | B5: 2150000
A6: Sales Revenue – Espresso | B6: 1620000
A7: Sales Revenue – Mocha | B7: 1740000
A8: Total Net Revenue | B8: =SUM(B5:B7) -> 5510000
A10: Cost of Goods Sold (COGS)
A11: Coffee Beans | B11: 385000
A12: Milk & Dairy | B12: 305000
A13: Cups, Lids, Napkins | B13: 210000
A14: Other Ingredients (syrups, cocoa, etc.) | B14: 130000
A15: Total COGS | B15: =SUM(B11:B14) -> 1030000
A16: Gross Profit | B16: =B8-B15 -> 4480000
A19: Operating Expenses - Payroll & People Costs
A20: Wages – Baristas (15×2) | B20: 1500000
A21: Salaries – Store Managers (15×1) | B21: 840000
A22: Payroll Taxes & Benefits | B22: 360000
A23: Total Payroll Costs | B23: =SUM(B20:B22) -> 2700000
A25: Operating Expenses - Occupancy & Store Costs
A26: Rent Expense | B26: 720000
A27: Utilities (Electric/Gas/Water) | B27: 175000
A28: Repairs & Maintenance | B28: 180000
A29: Cleaning & Sanitation | B29: 85000
A30: Total Occupancy & Store Costs | B30: =SUM(B26:B29) -> 1160000
A32: Operating Expenses - Operating & Admin
A33: Marketing & Promotions | B33: 110000
A34: POS / Software Subscriptions | B34: 60000
A35: Insurance Expense | B35: 75000
A36: Bank & Card Processing Fees | B36: 165000
A37: Delivery / Courier Fees | B37: 25000
A38: Office & Admin Supplies | B38: 30000
A39: Total Operating & Admin | B39: =SUM(B33:B38) -> 465000
A41: Total Operating Expenses | B41: =B23+B30+B39 -> 4325000
A42: Operating Income (EBIT) | B42: =B16-B41 -> 155000
A44: Other Income / (Expenses)
A45: Interest Expense | B45: 0
A46: Other Income | B46: 15000
A47: Net Other Income | B47: =B46+B45 -> 15000
...

Sheet Ratios
A1: 📈 Top 5 Financial Ratios
A2: =PandL!A2 -> Year ending 31st Dec 2025
A3: Ratio | B3: Numerator | C3: Denominator | D3: Result | E3: Details
A4: Current Ratio | B4: =CHOOSE(ROW()-3,'Balance Sheet'!$B$10,'Balance Sheet'!$B$25,PandL!$B$16,PandL!$B$42,PandL!$B$48) -> 380000 | C4: =CHOOSE(ROW()-3,'Balance Sheet'!$B$24,'Balance Sheet'!$B$30,PandL!$B$8,PandL!$B$8,'Balance Sheet'!$B$30) -> 320000 | D4: =IF(TopRatios[[#This Row],[Denominator]]=0,"",TopRatios[[#This Row],[Numerator]]/TopRatios[[#This Row],[Denominator]]) -> 1.1875 | E4: Measures liquidity: Current Assets ÷ Current Liabilities (ability to cover short-term obligations).
A5: Debt-to-Equity | B5: =CHOOSE(ROW()-3,'Balance Sheet'!$B$10,'Balance Sheet'!$B$25,PandL!$B$16,PandL!$B$42,PandL!$B$48) -> 320000 | C5: =CHOOSE(ROW()-3,'Balance Sheet'!$B$24,'Balance Sheet'!$B$30,PandL!$B$8,PandL!$B$8,'Balance Sheet'!$B$30) -> 900000 | D5: =IF(TopRatios[[#This Row],[Denominator]]=0,"",TopRatios[[#This Row],[Numerator]]/TopRatios[[#This Row],[Denominator]]) -> 0.35555556 | E5: Measures leverage: Total Liabilities ÷ Total Equity (how much financing comes from debt vs. owners).
A6: Gross Margin | B6: =CHOOSE(ROW()-3,'Balance Sheet'!$B$10,'Balance Sheet'!$B$25,PandL!$B$16,PandL!$B$42,PandL!$B$48) -> 4480000 | C6: =CHOOSE(ROW()-3,'Balance Sheet'!$B$24,'Balance Sheet'!$B$30,PandL!$B$8,PandL!$B$8,'Balance Sheet'!$B$30) -> 5510000 | D6: =IF(TopRatios[[#This Row],[Denominator]]=0,"",TopRatios[[#This Row],[Numerator]]/TopRatios[[#This Row],[Denominator]]) -> 0.81306715 | E6: Measures profitability: Gross Profit ÷ Total Net Revenue (profit after COGS as a % of sales).
A7: Operating Margin (EBIT) | B7: =CHOOSE(ROW()-3,'Balance Sheet'!$B$10,'Balance Sheet'!$B$25,PandL!$B$16,PandL!$B$42,PandL!$B$48) -> 155000 | C7: =CHOOSE(ROW()-3,'Balance Sheet'!$B$24,'Balance Sheet'!$B$30,PandL!$B$8,PandL!$B$8,'Balance Sheet'!$B$30) -> 5510000 | D7: =IF(TopRatios[[#This Row],[Denominator]]=0,"",TopRatios[[#This Row],[Numerator]]/TopRatios[[#This Row],[Denominator]]) -> 0.028130672 | E7: Measures operating efficiency: Operating Income (EBIT) ÷ Total Net Revenue (operating profit as a % of sales).
A8: Return on Equity (ROE) | B8: =CHOOSE(ROW()-3,'Balance Sheet'!$B$10,'Balance Sheet'!$B$25,PandL!$B$16,PandL!$B$42,PandL!$B$48) -> 170000 | C8: =CHOOSE(ROW()-3,'Balance Sheet'!$B$24,'Balance Sheet'!$B$30,PandL!$B$8,PandL!$B$8,'Balance Sheet'!$B$30) -> 900000 | D8: =IF(TopRatios[[#This Row],[Denominator]]=0,"",TopRatios[[#This Row],[Numerator]]/TopRatios[[#This Row],[Denominator]]) -> 0.18888889 | E8: Measures shareholder return: Net Income ÷ Total Equity (earnings generated per dollar of equity).
A10: All ratios update automatically when source financial statements change.
A12: 📊 Ratio Comparison: Our Business vs Tim Hortons (RBI)
A13: Ratio | B13: Our Business | C13: Competitor (Tim Hortons/RBI) | D13: Difference (Our - Comp) | E13: Notes
A14: {=INDEX(TopRatios[Ratio],ROW()-13)} -> Current Ratio | B14: {=INDEX(TopRatios[Result],ROW()-13)} -> 1.1875 | C14: {=INDEX(CompetitorRatios[Result],ROW()-13)} -> 1.0135261 | D14: =IF(RatioComparison[[#This Row],[Competitor (Tim Hortons/RBI)]]="","",RatioComparison[[#This Row],[Our Business]]-RatioComparison[[#This Row],[Competitor (Tim Hortons/RBI)]]) -> 0.17397388 | E14: =_xlfn.LET(_xlpm.r,RatioComparison[[#This Row],[Ratio]],_xlpm.d,RatioComparison[[#This Row],[Difference (Our - Comp)]],_xlpm.fmt,IF(OR(_xlpm.r="Gross Margin",_xlpm.r="Operating Margin (EBIT)",_xlpm.r="Return on Equity (ROE)"),"0.00%","0.00"),_xlpm.delta,TEXT(ABS(_xlpm.d),_xlpm.fmt),IF(_xlpm.d=0,"About the same as Tim Hortons.",IF(_xlpm.r="Debt-to-Equity",IF(_xlpm.d<0,"Better: lower leverage by "&_xlpm.delta&" (we use less debt).","Worse: higher leverage by "&_xlpm.delta&" (we use more debt)."),IF(_xlpm.d>0,"Better: higher than Tim Hortons by "&_xlpm.delta&".","Worse: lower than Tim Hortons by "&_xlpm.delta&".")))) -> Better: higher than Tim Hortons by 0.17.
A15: {=INDEX(TopRatios[Ratio],ROW()-13)} -> Debt-to-Equity | B15: {=INDEX(TopRatios[Result],ROW()-13)} -> 0.35555556 | C15: {=INDEX(CompetitorRatios[Result],ROW()-13)} -> 3.9452431 | D15: =IF(RatioComparison[[#This Row],[Competitor (Tim Hortons/RBI)]]="","",RatioComparison[[#This Row],[Our Business]]-RatioComparison[[#This Row],[Competitor (Tim Hortons/RBI)]]) -> -3.5896876 | E15: =_xlfn.LET(_xlpm.r,RatioComparison[[#This Row],[Ratio]],_xlpm.d,RatioComparison[[#This Row],[Difference (Our - Comp)]],_xlpm.fmt,IF(OR(_xlpm.r="Gross Margin",_xlpm.r="Operating Margin (EBIT)",_xlpm.r="Return on Equity (ROE)"),"0.00%","0.00"),_xlpm.delta,TEXT(ABS(_xlpm.d),_xlpm.fmt),IF(_xlpm.d=0,"About the same as Tim Hortons.",IF(_xlpm.r="Debt-to-Equity",IF(_xlpm.d<0,"Better: lower leverage by "&_xlpm.delta&" (we use less debt).","Worse: higher leverage by "&_xlpm.delta&" (we use more debt)."),IF(_xlpm.d>0,"Better: higher than Tim Hortons by "&_xlpm.delta&".","Worse: lower than Tim Hortons by "&_xlpm.delta&".")))) -> Better: lower leverage by 3.59 (we use less debt).
A16: {=INDEX(TopRatios[Ratio],ROW()-13)} -> Gross Margin | B16: {=INDEX(TopRatios[Result],ROW()-13)} -> 0.81306715 | C16: {=INDEX(CompetitorRatios[Result],ROW()-13)} -> 0.58267904 | D16: =IF(RatioComparison[[#This Row],[Competitor (Tim Hortons/RBI)]]="","",RatioComparison[[#This Row],[Our Business]]-RatioComparison[[#This Row],[Competitor (Tim Hortons/RBI)]]) -> 0.23038811 | E16: =_xlfn.LET(_xlpm.r,RatioComparison[[#This Row],[Ratio]],_xlpm.d,RatioComparison[[#This Row],[Difference (Our - Comp)]],_xlpm.fmt,IF(OR(_xlpm.r="Gross Margin",_xlpm.r="Operating Margin (EBIT)",_xlpm.r="Return on Equity (ROE)"),"0.00%","0.00"),_xlpm.delta,TEXT(ABS(_xlpm.d),_xlpm.fmt),IF(_xlpm.d=0,"About the same as Tim Hortons.",IF(_xlpm.r="Debt-to-Equity",IF(_xlpm.d<0,"Better: lower leverage by "&_xlpm.delta&" (we use less debt).","Worse: higher leverage by "&_xlpm.delta&" (we use more debt)."),IF(_xlpm.d>0,"Better: higher than Tim Hortons by "&_xlpm.delta&".","Worse: lower than Tim Hortons by "&_xlpm.delta&".")))) -> Better: higher than Tim Hortons by 23.04%.
A17: {=INDEX(TopRatios[Ratio],ROW()-13)} -> Operating Margin (EBIT) | B17: {=INDEX(TopRatios[Result],ROW()-13)} -> 0.028130672 | C17: {=INDEX(CompetitorRatios[Result],ROW()-13)} -> 0.28777064 | D17: =IF(RatioComparison[[#This Row],[Competitor (Tim Hortons/RBI)]]="","",RatioComparison[[#This Row],[Our Business]]-RatioComparison[[#This Row],[Competitor (Tim Hortons/RBI)]]) -> -0.25963997 | E17: =_xlfn.LET(_xlpm.r,RatioComparison[[#This Row],[Ratio]],_xlpm.d,RatioComparison[[#This Row],[Difference (Our - Comp)]],_xlpm.fmt,IF(OR(_xlpm.r="Gross Margin",_xlpm.r="Operating Margin (EBIT)",_xlpm.r="Return on Equity (ROE)"),"0.00%","0.00"),_xlpm.delta,TEXT(ABS(_xlpm.d),_xlpm.fmt),IF(_xlpm.d=0,"About the same as Tim Hortons.",IF(_xlpm.r="Debt-to-Equity",IF(_xlpm.d<0,"Better: lower leverage by "&_xlpm.delta&" (we use less debt).","Worse: higher leverage by "&_xlpm.delta&" (we use more debt)."),IF(_xlpm.d>0,"Better: higher than Tim Hortons by "&_xlpm.delta&".","Worse: lower than Tim Hortons by "&_xlpm.delta&".")))) -> Worse: lower than Tim Hortons by 25.96%.
A18: {=INDEX(TopRatios[Ratio],ROW()-13)} -> Return on Equity (ROE) | B18: {=INDEX(TopRatios[Result],ROW()-13)} -> 0.18888889 | C18: {=INDEX(CompetitorRatios[Result],ROW()-13)} -> 0.30549683 | D18: =IF(RatioComparison[[#This Row],[Competitor (Tim Hortons/RBI)]]="","",RatioComparison[[#This Row],[Our Business]]-RatioComparison[[#This Row],[Competitor (Tim Hortons/RBI)]]) -> -0.11660794 | E18: =_xlfn.LET(_xlpm.r,RatioComparison[[#This Row],[Ratio]],_xlpm.d,RatioComparison[[#This Row],[Difference (Our - Comp)]],_xlpm.fmt,IF(OR(_xlpm.r="Gross Margin",_xlpm.r="Operating Margin (EBIT)",_xlpm.r="Return on Equity (ROE)"),"0.00%","0.00"),_xlpm.delta,TEXT(ABS(_xlpm.d),_xlpm.fmt),IF(_xlpm.d=0,"About the same as Tim Hortons.",IF(_xlpm.r="Debt-to-Equity",IF(_xlpm.d<0,"Better: lower leverage by "&_xlpm.delta&" (we use less debt).","Worse: higher leverage by "&_xlpm.delta&" (we use more debt)."),IF(_xlpm.d>0,"Better: higher than Tim Hortons by "&_xlpm.delta&".","Worse: lower than Tim Hortons by "&_xlpm.delta&".")))) -> Worse: lower than Tim Hortons by 11.66%.

Sheet Competitor
A1: ☕ Competitor: Tim Hortons (Restaurant Brands International Inc.)
A2: Financials: FY2024 (published in 2025 Form 10-K / financial data sites)
A4: Key Inputs (USD millions)
A5: Total Revenues | B5: 8406
A6: Supply Chain Cost of Sales | B6: 2180
A7: Company Restaurant Expenses | B7: 1328
A8: Gross Profit (approx.) | B8: =B5-B6-B7 -> 4898
A9: Operating Income (EBIT) | B9: 2419
A10: Net Income | B10: 1445
A11: Total Current Assets | B11: 2173
A12: Total Current Liabilities | B12: 2144
A13: Total Liabilities | B13: 18661
A14: Total Shareholders' Equity | B14: 4730
A16: Sources
A17: Income statement totals (Revenue, Op. Income, Net Income, cost lines): | B17: SEC Form 10-K (FY ended Dec 31, 2024) filing | C17: https://www.sec.gov/Archives/edgar/data/1618755/000161875525000010/qsr-20241231.htm
A18: Balance sheet totals (Current Assets/Liabilities, Total Liabilities, Equity): | B18: StockAnalysis.com (QSR balance sheet) | C18: https://stockanalysis.com/stocks/qsr/financials/balance-sheet/
A20: Ratio | B20: Numerator | C20: Denominator | D20: Result | E20: Details
A21: Current Ratio | B21: =CHOOSE(ROW()-20,$B$11,$B$13,$B$8,$B$9,$B$10) -> 2173 | C21: =CHOOSE(ROW()-20,$B$12,$B$14,$B$5,$B$5,$B$14) -> 2144 | D21: =IF(CompetitorRatios[[#This Row],[Denominator]]=0,"",CompetitorRatios[[#This Row],[Numerator]]/CompetitorRatios[[#This Row],[Denominator]]) -> 1.0135261 | E21: Measures liquidity: Current Assets ÷ Current Liabilities.
A22: Debt-to-Equity | B22: =CHOOSE(ROW()-20,$B$11,$B$13,$B$8,$B$9,$B$10) -> 18661 | C22: =CHOOSE(ROW()-20,$B$12,$B$14,$B$5,$B$5,$B$14) -> 4730 | D22: =IF(CompetitorRatios[[#This Row],[Denominator]]=0,"",CompetitorRatios[[#This Row],[Numerator]]/CompetitorRatios[[#This Row],[Denominator]]) -> 3.9452431 | E22: Measures leverage: Total Liabilities ÷ Total Equity.
A23: Gross Margin | B23: =CHOOSE(ROW()-20,$B$11,$B$13,$B$8,$B$9,$B$10) -> 4898 | C23: =CHOOSE(ROW()-20,$B$12,$B$14,$B$5,$B$5,$B$14) -> 8406 | D23: =IF(CompetitorRatios[[#This Row],[Denominator]]=0,"",CompetitorRatios[[#This Row],[Numerator]]/CompetitorRatios[[#This Row],[Denominator]]) -> 0.58267904 | E23: Approx. profitability: (Revenue − direct costs) ÷ Revenue.
A24: Operating Margin (EBIT) | B24: =CHOOSE(ROW()-20,$B$11,$B$13,$B$8,$B$9,$B$10) -> 2419 | C24: =CHOOSE(ROW()-20,$B$12,$B$14,$B$5,$B$5,$B$14) -> 8406 | D24: =IF(CompetitorRatios[[#This Row],[Denominator]]=0,"",CompetitorRatios[[#This Row],[Numerator]]/CompetitorRatios[[#This Row],[Denominator]]) -> 0.28777064 | E24: Operating efficiency: EBIT ÷ Revenue.
A25: Return on Equity (ROE) | B25: =CHOOSE(ROW()-20,$B$11,$B$13,$B$8,$B$9,$B$10) -> 1445 | C25: =CHOOSE(ROW()-20,$B$12,$B$14,$B$5,$B$5,$B$14) -> 4730 | D25: =IF(CompetitorRatios[[#This Row],[Denominator]]=0,"",CompetitorRatios[[#This Row],[Numerator]]/CompetitorRatios[[#This Row],[Denominator]]) -> 0.30549683 | E25: Shareholder return: Net Income ÷ Total Equity.
